<?xml version="1.0" encoding="UTF-8"?>
<testng-results skipped="2" failed="1" total="3" passed="0">
  <reporter-output>
  </reporter-output>
  <suite name="Default suite" duration-ms="114932" started-at="2015-07-02T07:16:55Z" finished-at="2015-07-02T07:18:50Z">
    <groups>
    </groups>
    <test name="Default test" duration-ms="114932" started-at="2015-07-02T07:16:55Z" finished-at="2015-07-02T07:18:50Z">
      <class name="com.webdriver.CostcoTest.TestOrderCycle">
        <test-method status="PASS" signature="setUpTest()[pri:0, instance:com.webdriver.CostcoTest.TestOrderCycle@8d66b2]" name="setUpTest" is-config="true" duration-ms="7484" started-at="2015-07-02T12:46:55Z" finished-at="2015-07-02T12:47:02Z">
          <reporter-output>
          </reporter-output>
        </test-method> <!-- setUpTest -->
        <test-method status="FAIL" signature="launchApplication()[pri:0, instance:com.webdriver.CostcoTest.TestOrderCycle@8d66b2]" name="launchApplication" duration-ms="107419" started-at="2015-07-02T12:47:02Z" finished-at="2015-07-02T12:48:50Z">
          <exception class="java.lang.AssertionError">
            <message>
              <![CDATA[expected [true] but found [false]]]>
            </message>
            <full-stacktrace>
              <![CDATA[java.lang.AssertionError: expected [true] but found [false]
	at org.testng.Assert.fail(Assert.java:94)
	at org.testng.Assert.failNotEquals(Assert.java:496)
	at org.testng.Assert.assertTrue(Assert.java:42)
	at org.testng.Assert.assertTrue(Assert.java:52)
	at com.webdriver.CostcoTest.TestOrderCycle.launchApplication(TestOrderCycle.java:43)
	at sun.reflect.NativeMethodAccessorImpl.invoke0(Native Method)
	at sun.reflect.NativeMethodAccessorImpl.invoke(Unknown Source)
	at sun.reflect.DelegatingMethodAccessorImpl.invoke(Unknown Source)
	at java.lang.reflect.Method.invoke(Unknown Source)
	at org.testng.internal.MethodInvocationHelper.invokeMethod(MethodInvocationHelper.java:85)
	at org.testng.internal.Invoker.invokeMethod(Invoker.java:659)
	at org.testng.internal.Invoker.invokeTestMethod(Invoker.java:845)
	at org.testng.internal.Invoker.invokeTestMethods(Invoker.java:1153)
	at org.testng.internal.TestMethodWorker.invokeTestMethods(TestMethodWorker.java:125)
	at org.testng.internal.TestMethodWorker.run(TestMethodWorker.java:108)
	at org.testng.TestRunner.privateRun(TestRunner.java:771)
	at org.testng.TestRunner.run(TestRunner.java:621)
	at org.testng.SuiteRunner.runTest(SuiteRunner.java:357)
	at org.testng.SuiteRunner.runSequentially(SuiteRunner.java:352)
	at org.testng.SuiteRunner.privateRun(SuiteRunner.java:310)
	at org.testng.SuiteRunner.run(SuiteRunner.java:259)
	at org.testng.SuiteRunnerWorker.runSuite(SuiteRunnerWorker.java:52)
	at org.testng.SuiteRunnerWorker.run(SuiteRunnerWorker.java:86)
	at org.testng.TestNG.runSuitesSequentially(TestNG.java:1199)
	at org.testng.TestNG.runSuitesLocally(TestNG.java:1124)
	at org.testng.TestNG.run(TestNG.java:1032)
	at org.testng.remote.RemoteTestNG.run(RemoteTestNG.java:111)
	at org.testng.remote.RemoteTestNG.initAndRun(RemoteTestNG.java:204)
	at org.testng.remote.RemoteTestNG.main(RemoteTestNG.java:175)
]]>
            </full-stacktrace>
          </exception> <!-- java.lang.AssertionError -->
          <reporter-output>
          </reporter-output>
        </test-method> <!-- launchApplication -->
        <test-method status="SKIP" signature="LoginApplication()[pri:0, instance:com.webdriver.CostcoTest.TestOrderCycle@8d66b2]" name="LoginApplication" duration-ms="0" started-at="2015-07-02T12:48:50Z" depends-on-methods="com.webdriver.CostcoTest.TestOrderCycle.launchApplication" finished-at="2015-07-02T12:48:50Z">
          <exception class="java.lang.Throwable">
            <message>
              <![CDATA[Method TestOrderCycle.LoginApplication()[pri:0, instance:com.webdriver.CostcoTest.TestOrderCycle@8d66b2] depends on not successfully finished methods]]>
            </message>
            <full-stacktrace>
              <![CDATA[java.lang.Throwable: Method TestOrderCycle.LoginApplication()[pri:0, instance:com.webdriver.CostcoTest.TestOrderCycle@8d66b2] depends on not successfully finished methods
	at org.testng.internal.Invoker.invokeTestMethods(Invoker.java:1063)
	at org.testng.internal.TestMethodWorker.invokeTestMethods(TestMethodWorker.java:125)
	at org.testng.internal.TestMethodWorker.run(TestMethodWorker.java:108)
	at org.testng.TestRunner.privateRun(TestRunner.java:771)
	at org.testng.TestRunner.run(TestRunner.java:621)
	at org.testng.SuiteRunner.runTest(SuiteRunner.java:357)
	at org.testng.SuiteRunner.runSequentially(SuiteRunner.java:352)
	at org.testng.SuiteRunner.privateRun(SuiteRunner.java:310)
	at org.testng.SuiteRunner.run(SuiteRunner.java:259)
	at org.testng.SuiteRunnerWorker.runSuite(SuiteRunnerWorker.java:52)
	at org.testng.SuiteRunnerWorker.run(SuiteRunnerWorker.java:86)
	at org.testng.TestNG.runSuitesSequentially(TestNG.java:1199)
	at org.testng.TestNG.runSuitesLocally(TestNG.java:1124)
	at org.testng.TestNG.run(TestNG.java:1032)
	at org.testng.remote.RemoteTestNG.run(RemoteTestNG.java:111)
	at org.testng.remote.RemoteTestNG.initAndRun(RemoteTestNG.java:204)
	at org.testng.remote.RemoteTestNG.main(RemoteTestNG.java:175)
]]>
            </full-stacktrace>
          </exception> <!-- java.lang.Throwable -->
          <reporter-output>
          </reporter-output>
        </test-method> <!-- LoginApplication -->
        <test-method status="SKIP" signature="deleteDelAddress()[pri:0, instance:com.webdriver.CostcoTest.TestOrderCycle@8d66b2]" name="deleteDelAddress" duration-ms="0" started-at="2015-07-02T12:48:50Z" depends-on-methods="com.webdriver.CostcoTest.TestOrderCycle.LoginApplication" finished-at="2015-07-02T12:48:50Z">
          <exception class="java.lang.Throwable">
            <message>
              <![CDATA[Method TestOrderCycle.deleteDelAddress()[pri:0, instance:com.webdriver.CostcoTest.TestOrderCycle@8d66b2] depends on not successfully finished methods]]>
            </message>
            <full-stacktrace>
              <![CDATA[java.lang.Throwable: Method TestOrderCycle.deleteDelAddress()[pri:0, instance:com.webdriver.CostcoTest.TestOrderCycle@8d66b2] depends on not successfully finished methods
	at org.testng.internal.Invoker.invokeTestMethods(Invoker.java:1063)
	at org.testng.internal.TestMethodWorker.invokeTestMethods(TestMethodWorker.java:125)
	at org.testng.internal.TestMethodWorker.run(TestMethodWorker.java:108)
	at org.testng.TestRunner.privateRun(TestRunner.java:771)
	at org.testng.TestRunner.run(TestRunner.java:621)
	at org.testng.SuiteRunner.runTest(SuiteRunner.java:357)
	at org.testng.SuiteRunner.runSequentially(SuiteRunner.java:352)
	at org.testng.SuiteRunner.privateRun(SuiteRunner.java:310)
	at org.testng.SuiteRunner.run(SuiteRunner.java:259)
	at org.testng.SuiteRunnerWorker.runSuite(SuiteRunnerWorker.java:52)
	at org.testng.SuiteRunnerWorker.run(SuiteRunnerWorker.java:86)
	at org.testng.TestNG.runSuitesSequentially(TestNG.java:1199)
	at org.testng.TestNG.runSuitesLocally(TestNG.java:1124)
	at org.testng.TestNG.run(TestNG.java:1032)
	at org.testng.remote.RemoteTestNG.run(RemoteTestNG.java:111)
	at org.testng.remote.RemoteTestNG.initAndRun(RemoteTestNG.java:204)
	at org.testng.remote.RemoteTestNG.main(RemoteTestNG.java:175)
]]>
            </full-stacktrace>
          </exception> <!-- java.lang.Throwable -->
          <reporter-output>
          </reporter-output>
        </test-method> <!-- deleteDelAddress -->
      </class> <!-- com.webdriver.CostcoTest.TestOrderCycle -->
    </test> <!-- Default test -->
  </suite> <!-- Default suite -->
</testng-results>
